Workbook

Sheet Start Here
B2: BICOL HOME GOODS · CUSTOMER DATABASE CLEANUP
B3: One clean customer list from three messy files
B4: Three customer files (online store, Facebook Page orders and in-store loyalty sign-ups) were combined, cleaned, de-duplicated and checked, so the shop can move to one CRM and start a loyalty program. The raw file is kept untouched. Every change is logged.
B6: Report date | C6: 46295
B7: Prepared by | C7: Mary Rose Obsuna, Virtual Assistant
B8: Data | C8: Fictional sample. All names, emails and numbers are made up for demonstration.
B10: Sheets in this workbook
B11: Sheet | C11: What it holds
B12: Dashboard | C12: Headline numbers, data quality before and after, customer segments and where customers live. All live formulas.
B13: Customer Master | C13: The clean list: one row per customer, ready to import into a CRM. Checks and segments update on their own.
B14: Raw Combined | C14: The three source files stacked exactly as received. Never edited, so every change can be traced.
B15: Change Log | C15: Every field that changed: raw row, field, value before, value after and the rule applied.
B16: Duplicate Log | C16: Which raw rows were the same customer, how they were matched and what was kept.
B17: Follow-up Queue | C17: Customers missing an email, mobile or consent, with the next action, owner and status.
B18: Data Quality | C18: Scorecard on four standard checks, measured on the raw file and on the clean list, plus fixes by field.
B19: Data Dictionary | C19: What each column means, its format and the rule that keeps it clean.
B20: Lists | C20: Approved values used by the dropdowns (cities, provinces, consent, follow-up status).
B22: How the cleanup was done
B23: 1 Protect the original | C23: Combined the three exports into Raw Combined with a row number (R001...) and source reference, then left it untouched.
B24: 2 Standardize every field | C24: Names in proper case with extra spaces removed, emails in lowercase with domain typos fixed, one mobile format (+63 9XX XXX XXXX), one spelling per city, full province names, real dates, and numbers instead of text.
B25: 3 Find duplicates | C25: Matched rows by the same email first, then the same mobile number, then the same name and city. Each match was checked before merging.
B26: 4 Merge carefully | C26: Duplicates across sources were merged: orders and spend added up, earliest first order and latest last order kept. Rows exported twice from the same file were kept once.
B27: 5 Check and score | C27: Measured completeness, validity, consistency and uniqueness before and after. Added dropdowns and checks so new rows stay clean.
B28: 6 Hand over | C28: Customers with missing details went to the Follow-up Queue with a clear next step. The clean list is ready for CRM import.
B30: Color key
C31: Blue header: column names
C32: Light blue cell: needs a follow-up action
C33: Gray cell: formula, do not type over it

Sheet Dashboard
B2: BICOL HOME GOODS · CUSTOMER DATABASE
B3: Customer Data Cleanup Dashboard
B4: ="As of "&TEXT(AsOfDate,"mmmm d, yyyy")&" · Three source files combined, cleaned and checked" -> As of September 30, 2026 · Three source files combined, cleaned and checked
B6: Raw rows received | E6: Duplicate rows removed | H6: Fields corrected | K6: Clean customers
B7: =COUNTA('Raw Combined'!A2:A269) -> 268 | E7: =B7-K7 -> 62 | H7: =COUNTA('Change Log'!A2:A1657) -> 1656 | K7: =COUNTA('Customer Master'!A2:A207) -> 206
B8: From 3 source files | E8: =TEXT(COUNTA('Duplicate Log'!A2:A54),"0")&" customers matched" -> 53 customers matched | H8: Every change logged | K8: =TEXT(COUNTIF('Customer Master'!S2:S207,"Complete"),"0")&" complete, ready for CRM" -> 185 complete, ready for CRM
B10: Data quality score | E10: Total customer spend | H10: VIP customers | K10: Follow-ups open
B11: ='Data Quality'!E10 -> 0.99745146 | E11: =SUM('Customer Master'!L2:L207) -> 2009530 | H11: =COUNTIF('Customer Master'!P2:P207,"VIP") -> 33 | K11: =COUNTIF('Follow-up Queue'!J2:J22,"Open") -> 21
B12: ="Up from "&TEXT('Data Quality'!D10,"0%")&" in the raw file" -> Up from 63% in the raw file | E12: =TEXT(SUM('Customer Master'!K2:K207),"#,##0")&" orders on record" -> 1,555 orders on record | H12: =TEXT(SUMIF('Customer Master'!P2:P207,"VIP",'Customer Master'!L2:L207)/E11,"0%")&" of all spend" -> 48% of all spend | K12: Missing email, mobile or consent
B14: Data quality, before and after
B15: Check | C15: Raw file | D15: Clean list
B16: Completeness | C16: ='Data Quality'!D6 -> 0.978 | D16: ='Data Quality'!E6 -> 0.98980583
B17: Validity | C17: ='Data Quality'!D7 -> 0.3427 | D17: ='Data Quality'!E7 -> 1
B18: Consistency | C18: ='Data Quality'!D8 -> 0.4142 | D18: ='Data Quality'!E8 -> 1
B19: Uniqueness | C19: ='Data Quality'!D9 -> 0.7687 | D19: ='Data Quality'!E9 -> 1
B30: Customer segments
B31: Segment | C31: Customers | D31: Spend
B32: VIP | C32: =COUNTIF('Customer Master'!P2:P207,B32) -> 33 | D32: =SUMIF('Customer Master'!P2:P207,B32,'Customer Master'!L2:L207) -> 963450
B33: Regular | C33: =COUNTIF('Customer Master'!P2:P207,B33) -> 68 | D33: =SUMIF('Customer Master'!P2:P207,B33,'Customer Master'!L2:L207) -> 547270
B34: New | C34: =COUNTIF('Customer Master'!P2:P207,B34) -> 26 | D34: =SUMIF('Customer Master'!P2:P207,B34,'Customer Master'!L2:L207) -> 65880
B35: At risk | C35: =COUNTIF('Customer Master'!P2:P207,B35) -> 44 | D35: =SUMIF('Customer Master'!P2:P207,B35,'Customer Master'!L2:L207) -> 294900
B36: Lapsed | C36: =COUNTIF('Customer Master'!P2:P207,B36) -> 35 | D36: =SUMIF('Customer Master'!P2:P207,B36,'Customer Master'!L2:L207) -> 138030
B46: Where customers live
B47: Province | C47: Customers | D47: Share
B48: Camarines Sur | C48: =COUNTIF('Customer Master'!G2:G207,B48) -> 106 | D48: =C48/COUNTA('Customer Master'!A2:A207) -> 0.51456311
B49: Albay | C49: =COUNTIF('Customer Master'!G2:G207,B49) -> 59 | D49: =C49/COUNTA('Customer Master'!A2:A207) -> 0.28640777
B50: Sorsogon | C50: =COUNTIF('Customer Master'!G2:G207,B50) -> 16 | D50: =C50/COUNTA('Customer Master'!A2:A207) -> 0.077669903
B51: Camarines Norte | C51: =COUNTIF('Customer Master'!G2:G207,B51) -> 14 | D51: =C51/COUNTA('Customer Master'!A2:A207) -> 0.067961165
B52: Catanduanes | C52: =COUNTIF('Customer Master'!G2:G207,B52) -> 8 | D52: =C52/COUNTA('Customer Master'!A2:A207) -> 0.038834951
B53: Masbate | C53: =COUNTIF('Customer Master'!G2:G207,B53) -> 3 | D53: =C53/COUNTA('Customer Master'!A2:A207) -> 0.014563107
B62: Rows received by source | G62: Duplicates found by rule
B63: Source | C63: Raw rows | D63: Share | G63: Match rule | I63: Customers
B64: Online store | C64: =COUNTIF('Raw Combined'!B2:B269,"WEB") -> 109 | D64: =C64/COUNTA('Raw Combined'!A2:A269) -> 0.40671642 | G64: Same email | I64: =COUNTIF('Duplicate Log'!F2:F54,G64) -> 49
B65: Facebook Page | C65: =COUNTIF('Raw Combined'!B2:B269,"FB") -> 82 | D65: =C65/COUNTA('Raw Combined'!A2:A269) -> 0.30597015 | G65: Same mobile number | I65: =COUNTIF('Duplicate Log'!F2:F54,G65) -> 3
B66: In-store sign-ups | C66: =COUNTIF('Raw Combined'!B2:B269,"POS") -> 77 | D66: =C66/COUNTA('Raw Combined'!A2:A269) -> 0.28731343 | G66: Same name and city | I66: =COUNTIF('Duplicate Log'!F2:F54,G66) -> 1
B68: All numbers on this sheet are formulas that read the other sheets. Edit Customer Master and the dashboard updates.

Sheet Customer Master
A1: Customer ID | B1: First Name | C1: Last Name | D1: Email | E1: Mobile | F1: City | G1: Province | H1: Sources | I1: First Order | J1: Last Order | K1: Orders | L1: Total Spent | M1: Avg Order | N1: Consent | O1: Days Since Last Order | P1: Segment | Q1: Email Check | R1: Mobile Check | S1: Record Status | T1: Raw Rows
A2: BHG-10001 | B2: Fritz | C2: Francisco | D2: ffrancisco45@example.com | E2: +63 961 555 3755 | F2: Daraga | G2: Albay | H2: FB | I2: 44991 | J2: 45821 | K2: 2 | L2: 3390 | M2: =IFERROR(L2/K2,0) -> 1695 | O2: =IF(J2="","",AsOfDate-J2) -> 474 | P2: =IF(A2="","",IF(AsOfDate-I2<=90,"New",IF(AND(O2<=180,L2>=15000),"VIP",IF(O2<=180,"Regular",IF(O2<=365,"At risk","Lapsed"))))) -> Lapsed | Q2: =IF(D2="","Missing",IF(COUNTIF($D$2:$D$207,D2)>1,"Duplicate",IF(AND(LEN(D2)-LEN(SUBSTITUTE(D2,"@",""))=1,ISNUMBER(SEARCH(".",D2,SEARCH("@",D2))),ISERROR(SEARCH(" ",D2))),"Valid","Invalid"))) -> Valid | R2: =IF(E2="","Missing",IF(COUNTIF($E$2:$E$207,E2)>1,"Duplicate",IF(AND(LEN(E2)=16,LEFT(E2,5)="+63 9"),"Valid","Check"))) -> Valid | S2: =IF(AND(Q2="Valid",R2="Valid",N2<>""),"Complete","Needs follow-up") -> Needs follow-up | T2: R127
A3: BHG-10002 | B3: Precious | C3: Briones | D3: pbriones89@example.com | E3: +63 920 555 2968 | F3: Naga City | G3: Camarines Sur | H3: WEB | I3: 45046 | J3: 45446 | K3: 3 | L3: 2010 | M3: =IFERROR(L3/K3,0) -> 670 | N3: No | O3: =IF(J3="","",AsOfDate-J3) -> 849 | P3: =IF(A3="","",IF(AsOfDate-I3<=90,"New",IF(AND(O3<=180,L3>=15000),"VIP",IF(O3<=180,"Regular",IF(O3<=365,"At risk","Lapsed"))))) -> Lapsed | Q3: =IF(D3="","Missing",IF(COUNTIF($D$2:$D$207,D3)>1,"Duplicate",IF(AND(LEN(D3)-LEN(SUBSTITUTE(D3,"@",""))=1,ISNUMBER(SEARCH(".",D3,SEARCH("@",D3))),ISERROR(SEARCH(" ",D3))),"Valid","Invalid"))) -> Valid | R3: =IF(E3="","Missing",IF(COUNTIF($E$2:$E$207,E3)>1,"Duplicate",IF(AND(LEN(E3)=16,LEFT(E3,5)="+63 9"),"Valid","Check"))) -> Valid | S3: =IF(AND(Q3="Valid",R3="Valid",N3<>""),"Complete","Needs follow-up") -> Complete | T3: R019
A4: BHG-10003 | B4: Gemma | C4: Padilla | D4: gemma.padilla@example.com | E4: +63 998 555 4416 | F4: Virac | G4: Catanduanes | H4: WEB | I4: 45061 | J4: 45574 | K4: 2 | L4: 1480 | M4: =IFERROR(L4/K4,0) -> 740 | N4: No | O4: =IF(J4="","",AsOfDate-J4) -> 721 | P4: =IF(A4="","",IF(AsOfDate-I4<=90,"New",IF(AND(O4<=180,L4>=15000),"VIP",IF(O4<=180,"Regular",IF(O4<=365,"At risk","Lapsed"))))) -> Lapsed | Q4: =IF(D4="","Missing",IF(COUNTIF($D$2:$D$207,D4)>1,"Duplicate",IF(AND(LEN(D4)-LEN(SUBSTITUTE(D4,"@",""))=1,ISNUMBER(SEARCH(".",D4,SEARCH("@",D4))),ISERROR(SEARCH(" ",D4))),"Valid","Invalid"))) -> Valid | R4: =IF(E4="","Missing",IF(COUNTIF($E$2:$E$207,E4)>1,"Duplicate",IF(AND(LEN(E4)=16,LEFT(E4,5)="+63 9"),"Valid","Check"))) -> Valid | S4: =IF(AND(Q4="Valid",R4="Valid",N4<>""),"Complete","Needs follow-up") -> Complete | T4: R052
A5: BHG-10004 | B5: Nico | C5: Torres | D5: nico.torres@mail.example.com | E5: +63 977 555 0129 | F5: Naga City | G5: Camarines Sur | H5: FB | I5: 45074 | J5: 45891 | K5: 5 | L5: 6910 | M5: =IFERROR(L5/K5,0) -> 1382 | N5: No | O5: =IF(J5="","",AsOfDate-J5) -> 404 | P5: =IF(A5="","",IF(AsOfDate-I5<=90,"New",IF(AND(O5<=180,L5>=15000),"VIP",IF(O5<=180,"Regular",IF(O5<=365,"At risk","Lapsed"))))) -> Lapsed | Q5: =IF(D5="","Missing",IF(COUNTIF($D$2:$D$207,D5)>1,"Duplicate",IF(AND(LEN(D5)-LEN(SUBSTITUTE(D5,"@",""))=1,ISNUMBER(SEARCH(".",D5,SEARCH("@",D5))),ISERROR(SEARCH(" ",D5))),"Valid","Invalid"))) -> Valid | R5: =IF(E5="","Missing",IF(COUNTIF($E$2:$E$207,E5)>1,"Duplicate",IF(AND(LEN(E5)=16,LEFT(E5,5)="+63 9"),"Valid","Check"))) -> Valid | S5: =IF(AND(Q5="Valid",R5="Valid",N5<>""),"Complete","Needs follow-up") -> Complete | T5: R161
A6: BHG-10005 | B6: Gio | C6: Garcia | D6: ggarcia53@example.com | E6: +63 998 555 5135 | F6: Legazpi City | G6: Albay | H6: WEB | I6: 45076 | J6: 45463 | K6: 4 | L6: 3200 | M6: =IFERROR(L6/K6,0) -> 800 | N6: Yes | O6: =IF(J6="","",AsOfDate-J6) -> 832 | P6: =IF(A6="","",IF(AsOfDate-I6<=90,"New",IF(AND(O6<=180,L6>=15000),"VIP",IF(O6<=180,"Regular",IF(O6<=365,"At risk","Lapsed"))))) -> Lapsed | Q6: =IF(D6="","Missing",IF(COUNTIF($D$2:$D$207,D6)>1,"Duplicate",IF(AND(LEN(D6)-LEN(SUBSTITUTE(D6,"@",""))=1,ISNUMBER(SEARCH(".",D6,SEARCH("@",D6))),ISERROR(SEARCH(" ",D6))),"Valid","Invalid"))) -> Valid | R6: =IF(E6="","Missing",IF(COUNTIF($E$2:$E$207,E6)>1,"Duplicate",IF(AND(LEN(E6)=16,LEFT(E6,5)="+63 9"),"Valid","Check"))) -> Valid | S6: =IF(AND(Q6="Valid",R6="Valid",N6<>""),"Complete","Needs follow-up") -> Complete | T6: R045
A7: BHG-10006 | B7: Carlo | C7: Cortez | D7: carlo.cortez@example.net | E7: +63 977 555 6591 | F7: Legazpi City | G7: Albay | H7: FB | I7: 45086 | J7: 45155 | K7: 2 | L7: 2220 | M7: =IFERROR(L7/K7,0) -> 1110 | N7: Yes | O7: =IF(J7="","",AsOfDate-J7) -> 1140 | P7: =IF(A7="","",IF(AsOfDate-I7<=90,"New",IF(AND(O7<=180,L7>=15000),"VIP",IF(O7<=180,"Regular",IF(O7<=365,"At risk","Lapsed"))))) -> Lapsed | Q7: =IF(D7="","Missing",IF(COUNTIF($D$2:$D$207,D7)>1,"Duplicate",IF(AND(LEN(D7)-LEN(SUBSTITUTE(D7,"@",""))=1,ISNUMBER(SEARCH(".",D7,SEARCH("@",D7))),ISERROR(SEARCH(" ",D7))),"Valid","Invalid"))) -> Valid | R7: =IF(E7="","Missing",IF(COUNTIF($E$2:$E$207,E7)>1,"Duplicate",IF(AND(LEN(E7)=16,LEFT(E7,5)="+63 9"),"Valid","Check"))) -> Valid | S7: =IF(AND(Q7="Valid",R7="Valid",N7<>""),"Complete","Needs follow-up") -> Complete | T7: R148
A8: BHG-10007 | B8: Aira | C8: Pascual | D8: aira.pascual@example.com | F8: Pili | G8: Camarines Sur | H8: POS | I8: 45089 | J8: 46055 | K8: 2 | L8: 3320 | M8: =IFERROR(L8/K8,0) -> 1660 | N8: No | O8: =IF(J8="","",AsOfDate-J8) -> 240 | P8: =IF(A8="","",IF(AsOfDate-I8<=90,"New",IF(AND(O8<=180,L8>=15000),"VIP",IF(O8<=180,"Regular",IF(O8<=365,"At risk","Lapsed"))))) -> At risk | Q8: =IF(D8="","Missing",IF(COUNTIF($D$2:$D$207,D8)>1,"Duplicate",IF(AND(LEN(D8)-LEN(SUBSTITUTE(D8,"@",""))=1,ISNUMBER(SEARCH(".",D8,SEARCH("@",D8))),ISERROR(SEARCH(" ",D8))),"Valid","Invalid"))) -> Valid | R8: =IF(E8="","Missing",IF(COUNTIF($E$2:$E$207,E8)>1,"Duplicate",IF(AND(LEN(E8)=16,LEFT(E8,5)="+63 9"),"Valid","Check"))) -> Missing | S8: =IF(AND(Q8="Valid",R8="Valid",N8<>""),"Complete","Needs follow-up") -> Needs follow-up | T8: R216
A9: BHG-10008 | B9: Aira | C9: Ignacio | D9: aira.ignacio@example.com | E9: +63 928 555 5809 | F9: Daet | G9: Camarines Norte | H9: FB | I9: 45090 | J9: 45376 | K9: 2 | L9: 3400 | M9: =IFERROR(L9/K9,0) -> 1700 | N9: Yes | O9: =IF(J9="","",AsOfDate-J9) -> 919 | P9: =IF(A9="","",IF(AsOfDate-I9<=90,"New",IF(AND(O9<=180,L9>=15000),"VIP",IF(O9<=180,"Regular",IF(O9<=365,"At risk","Lapsed"))))) -> Lapsed | Q9: =IF(D9="","Missing",IF(COUNTIF($D$2:$D$207,D9)>1,"Duplicate",IF(AND(LEN(D9)-LEN(SUBSTITUTE(D9,"@",""))=1,ISNUMBER(SEARCH(".",D9,SEARCH("@",D9))),ISERROR(SEARCH(" ",D9))),"Valid","Invalid"))) -> Valid | R9: =IF(E9="","Missing",IF(COUNTIF($E$2:$E$207,E9)>1,"Duplicate",IF(AND(LEN(E9)=16,LEFT(E9,5)="+63 9"),"Valid","Check"))) -> Valid | S9: =IF(AND(Q9="Valid",R9="Valid",N9<>""),"Complete","Needs follow-up") -> Complete | T9: R146
A10: BHG-10009 | B10: Carlo | C10: Soriano | D10: carlo.soriano@example.com | E10: +63 917 555 3722 | F10: Daraga | G10: Albay | H10: WEB | I10: 45091 | J10: 46246 | K10: 24 | L10: 38110 | M10: =IFERROR(L10/K10,0) -> 1587.9167 | N10: No | O10: =IF(J10="","",AsOfDate-J10) -> 49 | P10: =IF(A10="","",IF(AsOfDate-I10<=90,"New",IF(AND(O10<=180,L10>=15000),"VIP",IF(O10<=180,"Regular",IF(O10<=365,"At risk","Lapsed"))))) -> VIP | Q10: =IF(D10="","Missing",IF(COUNTIF($D$2:$D$207,D10)>1,"Duplicate",IF(AND(LEN(D10)-LEN(SUBSTITUTE(D10,"@",""))=1,ISNUMBER(SEARCH(".",D10,SEARCH("@",D10))),ISERROR(SEARCH(" ",D10))),"Valid","Invalid"))) -> Valid | R10: =IF(E10="","Missing",IF(COUNTIF($E$2:$E$207,E10)>1,"Duplicate",IF(AND(LEN(E10)=16,LEFT(E10,5)="+63 9"),"Valid","Check"))) -> Valid | S10: =IF(AND(Q10="Valid",R10="Valid",N10<>""),"Complete","Needs follow-up") -> Complete | T10: R069
A11: BHG-10010 | B11: Jomar | C11: Cruz | D11: jomar.cruz@example.net | E11: +63 917 555 4023 | F11: Naga City | G11: Camarines Sur | H11: WEB + POS | I11: 45093 | J11: 45959 | K11: 5 | L11: 8920 | M11: =IFERROR(L11/K11,0) -> 1784 | N11: Yes | O11: =IF(J11="","",AsOfDate-J11) -> 336 | P11: =IF(A11="","",IF(AsOfDate-I11<=90,"New",IF(AND(O11<=180,L11>=15000),"VIP",IF(O11<=180,"Regular",IF(O11<=365,"At risk","Lapsed"))))) -> At risk | Q11: =IF(D11="","Missing",IF(COUNTIF($D$2:$D$207,D11)>1,"Duplicate",IF(AND(LEN(D11)-LEN(SUBSTITUTE(D11,"@",""))=1,ISNUMBER(SEARCH(".",D11,SEARCH("@",D11))),ISERROR(SEARCH(" ",D11))),"Valid","Invalid"))) -> Valid | R11: =IF(E11="","Missing",IF(COUNTIF($E$2:$E$207,E11)>1,"Duplicate",IF(AND(LEN(E11)=16,LEFT(E11,5)="+63 9"),"Valid","Check"))) -> Valid | S11: =IF(AND(Q11="Valid",R11="Valid",N11<>""),"Complete","Needs follow-up") -> Complete | T11: R005, R201
A12: BHG-10011 | B12: Cedric | C12: Fernandez | D12: cedric.fernandez@example.com | E12: +63 995 555 6077 | F12: Daraga | G12: Albay | H12: WEB + FB + POS | I12: 45096 | J12: 46262 | K12: 29 | L12: 35060 | M12: =IFERROR(L12/K12,0) -> 1208.9655 | N12: Yes | O12: =IF(J12="","",AsOfDate-J12) -> 33 | P12: =IF(A12="","",IF(AsOfDate-I12<=90,"New",IF(AND(O12<=180,L12>=15000),"VIP",IF(O12<=180,"Regular",IF(O12<=365,"At risk","Lapsed"))))) -> VIP | Q12: =IF(D12="","Missing",IF(COUNTIF($D$2:$D$207,D12)>1,"Duplicate",IF(AND(LEN(D12)-LEN(SUBSTITUTE(D12,"@",""))=1,ISNUMBER(SEARCH(".",D12,SEARCH("@",D12))),ISERROR(SEARCH(" ",D12))),"Valid","Invalid"))) -> Valid | R12: =IF(E12="","Missing",IF(COUNTIF($E$2:$E$207,E12)>1,"Duplicate",IF(AND(LEN(E12)=16,LEFT(E12,5)="+63 9"),"Valid","Check"))) -> Valid | S12: =IF(AND(Q12="Valid",R12="Valid",N12<>""),"Complete","Needs follow-up") -> Complete | T12: R015, R183, R245
A13: BHG-10012 | B13: Flor | C13: Evangelista | D13: flor.evangelista@example.com | E13: +63 918 555 6322 | F13: Naga City | G13: Camarines Sur | H13: FB | I13: 45100 | J13: 46246 | K13: 33 | L13: 51710 | M13: =IFERROR(L13/K13,0) -> 1566.9697 | N13: Yes | O13: =IF(J13="","",AsOfDate-J13) -> 49 | P13: =IF(A13="","",IF(AsOfDate-I13<=90,"New",IF(AND(O13<=180,L13>=15000),"VIP",IF(O13<=180,"Regular",IF(O13<=365,"At risk","Lapsed"))))) -> VIP | Q13: =IF(D13="","Missing",IF(COUNTIF($D$2:$D$207,D13)>1,"Duplicate",IF(AND(LEN(D13)-LEN(SUBSTITUTE(D13,"@",""))=1,ISNUMBER(SEARCH(".",D13,SEARCH("@",D13))),ISERROR(SEARCH(" ",D13))),"Valid","Invalid"))) -> Valid | R13: =IF(E13="","Missing",IF(COUNTIF($E$2:$E$207,E13)>1,"Duplicate",IF(AND(LEN(E13)=16,LEFT(E13,5)="+63 9"),"Valid","Check"))) -> Valid | S13: =IF(AND(Q13="Valid",R13="Valid",N13<>""),"Complete","Needs follow-up") -> Complete | T13: R180, R182
A14: BHG-10013 | B14: Nina | C14: Hidalgo | D14: nina.hidalgo@example.com | E14: +63 977 555 4270 | F14: Naga City | G14: Camarines Sur | H14: WEB | I14: 45104 | J14: 45160 | K14: 4 | L14: 6080 | M14: =IFERROR(L14/K14,0) -> 1520 | N14: Yes | O14: =IF(J14="","",AsOfDate-J14) -> 1135 | P14: =IF(A14="","",IF(AsOfDate-I14<=90,"New",IF(AND(O14<=180,L14>=15000),"VIP",IF(O14<=180,"Regular",IF(O14<=365,"At risk","Lapsed"))))) -> Lapsed | Q14: =IF(D14="","Missing",IF(COUNTIF($D$2:$D$207,D14)>1,"Duplicate",IF(AND(LEN(D14)-LEN(SUBSTITUTE(D14,"@",""))=1,ISNUMBER(SEARCH(".",D14,SEARCH("@",D14))),ISERROR(SEARCH(" ",D14))),"Valid","Invalid"))) -> Valid | R14: =IF(E14="","Missing",IF(COUNTIF($E$2:$E$207,E14)>1,"Duplicate",IF(AND(LEN(E14)=16,LEFT(E14,5)="+63 9"),"Valid","Check"))) -> Valid | S14: =IF(AND(Q14="Valid",R14="Valid",N14<>""),"Complete","Needs follow-up") -> Complete | T14: R029
A15: BHG-10014 | B15: Aira | C15: Santiago | D15: aira.santiago@example.com | E15: +63 918 555 8391 | F15: Naga City | G15: Camarines Sur | H15: FB | I15: 45115 | J15: 45301 | K15: 4 | L15: 7510 | M15: =IFERROR(L15/K15,0) -> 1877.5 | N15: No | O15: =IF(J15="","",AsOfDate-J15) -> 994 | P15: =IF(A15="","",IF(AsOfDate-I15<=90,"New",IF(AND(O15<=180,L15>=15000),"VIP",IF(O15<=180,"Regular",IF(O15<=365,"At risk","Lapsed"))))) -> Lapsed | Q15: =IF(D15="","Missing",IF(COUNTIF($D$2:$D$207,D15)>1,"Duplicate",IF(AND(LEN(D15)-LEN(SUBSTITUTE(D15,"@",""))=1,ISNUMBER(SEARCH(".",D15,SEARCH("@",D15))),ISERROR(SEARCH(" ",D15))),"Valid","Invalid"))) -> Valid | R15: =IF(E15="","Missing",IF(COUNTIF($E$2:$E$207,E15)>1,"Duplicate",IF(AND(LEN(E15)=16,LEFT(E15,5)="+63 9"),"Valid","Check"))) -> Valid | S15: =IF(AND(Q15="Valid",R15="Valid",N15<>""),"Complete","Needs follow-up") -> Complete | T15: R123
A16: BHG-10015 | B16: Pauline | C16: Cruz | D16: pauline.cruz@example.com | E16: +63 998 555 8552 | F16: Naga City | G16: Camarines Sur | H16: WEB | I16: 45122 | J16: 45122 | K16: 1 | L16: 920 | M16: =IFERROR(L16/K16,0) -> 920 | N16: Yes | O16: =IF(J16="","",AsOfDate-J16) -> 1173 | P16: =IF(A16="","",IF(AsOfDate-I16<=90,"New",IF(AND(O16<=180,L16>=15000),"VIP",IF(O16<=180,"Regular",IF(O16<=365,"At risk","Lapsed"))))) -> Lapsed | Q16: =IF(D16="","Missing",IF(COUNTIF($D$2:$D$207,D16)>1,"Duplicate",IF(AND(LEN(D16)-LEN(SUBSTITUTE(D16,"@",""))=1,ISNUMBER(SEARCH(".",D16,SEARCH("@",D16))),ISERROR(SEARCH(" ",D16))),"Valid","Invalid"))) -> Valid | R16: =IF(E16="","Missing",IF(COUNTIF($E$2:$E$207,E16)>1,"Duplicate",IF(AND(LEN(E16)=16,LEFT(E16,5)="+63 9"),"Valid","Check"))) -> Valid | S16: =IF(AND(Q16="Valid",R16="Valid",N16<>""),"Complete","Needs follow-up") -> Complete | T16: R009, R039
A17: BHG-10016 | B17: Hannah | C17: Cortez | D17: hannah.cortez@example.com | E17: +63 918 555 7216 | F17: Buhi | G17: Camarines Sur | H17: FB | I17: 45124 | J17: 45124 | K17: 1 | L17: 1860 | M17: =IFERROR(L17/K17,0) -> 1860 | N17: No | O17: =IF(J17="","",AsOfDate-J17) -> 1171 | P17: =IF(A17="","",IF(AsOfDate-I17<=90,"New",IF(AND(O17<=180,L17>=15000),"VIP",IF(O17<=180,"Regular",IF(O17<=365,"At risk","Lapsed"))))) -> Lapsed | Q17: =IF(D17="","Missing",IF(COUNTIF($D$2:$D$207,D17)>1,"Duplicate",IF(AND(LEN(D17)-LEN(SUBSTITUTE(D17,"@",""))=1,ISNUMBER(SEARCH(".",D17,SEARCH("@",D17))),ISERROR(SEARCH(" ",D17))),"Valid","Invalid"))) -> Valid | R17: =IF(E17="","Missing",IF(COUNTIF($E$2:$E$207,E17)>1,"Duplicate",IF(AND(LEN(E17)=16,LEFT(E17,5)="+63 9"),"Valid","Check"))) -> Valid | S17: =IF(AND(Q17="Valid",R17="Valid",N17<>""),"Complete","Needs follow-up") -> Complete | T17: R184
A18: BHG-10017 | B18: Erika | C18: Francisco | D18: erika.francisco@example.org | E18: +63 919 555 4129 | F18: Naga City | G18: Camarines Sur | H18: WEB | I18: 45134 | J18: 45733 | K18: 2 | L18: 1940 | M18: =IFERROR(L18/K18,0) -> 970 | N18: Yes | O18: =IF(J18="","",AsOfDate-J18) -> 562 | P18: =IF(A18="","",IF(AsOfDate-I18<=90,"New",IF(AND(O18<=180,L18>=15000),"VIP",IF(O18<=180,"Regular",IF(O18<=365,"At risk","Lapsed"))))) -> Lapsed | Q18: =IF(D18="","Missing",IF(COUNTIF($D$2:$D$207,D18)>1,"Duplicate",IF(AND(LEN(D18)-LEN(SUBSTITUTE(D18,"@",""))=1,ISNUMBER(SEARCH(".",D18,SEARCH("@",D18))),ISERROR(SEARCH(" ",D18))),"Valid","Invalid"))) -> Valid | R18: =IF(E18="","Missing",IF(COUNTIF($E$2:$E$207,E18)>1,"Duplicate",IF(AND(LEN(E18)=16,LEFT(E18,5)="+63 9"),"Valid","Check"))) -> Valid | S18: =IF(AND(Q18="Valid",R18="Valid",N18<>""),"Complete","Needs follow-up") -> Complete | T18: R049, R091
A19: BHG-10018 | B19: Dolor | C19: Garcia | D19: dolor.garcia@mail.example.com | E19: +63 954 555 7220 | F19: Pili | G19: Camarines Sur | H19: POS | I19: 45148 | J19: 45598 | K19: 5 | L19: 8810 | M19: =IFERROR(L19/K19,0) -> 1762 | N19: No | O19: =IF(J19="","",AsOfDate-J19) -> 697 | P19: =IF(A19="","",IF(AsOfDate-I19<=90,"New",IF(AND(O19<=180,L19>=15000),"VIP",IF(O19<=180,"Regular",IF(O19<=365,"At risk","Lapsed"))))) -> Lapsed | Q19: =IF(D19="","Missing",IF(COUNTIF($D$2:$D$207,D19)>1,"Duplicate",IF(AND(LEN(D19)-LEN(SUBSTITUTE(D19,"@",""))=1,ISNUMBER(SEARCH(".",D19,SEARCH("@",D19))),ISERROR(SEARCH(" ",D19))),"Valid","Invalid"))) -> Valid | R19: =IF(E19="","Missing",IF(COUNTIF($E$2:$E$207,E19)>1,"Duplicate",IF(AND(LEN(E19)=16,LEFT(E19,5)="+63 9"),"Valid","Check"))) -> Valid | S19: =IF(AND(Q19="Valid",R19="Valid",N19<>""),"Complete","Needs follow-up") -> Complete | T19: R246
A20: BHG-10019 | B20: Ronald | C20: Nolasco | E20: +63 961 555 8956 | F20: Naga City | G20: Camarines Sur | H20: POS | I20: 45149 | J20: 46265 | K20: 22 | L20: 23280 | M20: =IFERROR(L20/K20,0) -> 1058.1818 | N20: Yes | O20: =IF(J20="","",AsOfDate-J20) -> 30 | P20: =IF(A20="","",IF(AsOfDate-I20<=90,"New",IF(AND(O20<=180,L20>=15000),"VIP",IF(O20<=180,"Regular",IF(O20<=365,"At risk","Lapsed"))))) -> VIP | Q20: =IF(D20="","Missing",IF(COUNTIF($D$2:$D$207,D20)>1,"Duplicate",IF(AND(LEN(D20)-LEN(SUBSTITUTE(D20,"@",""))=1,ISNUMBER(SEARCH(".",D20,SEARCH("@",D20))),ISERROR(SEARCH(" ",D20))),"Valid","Invalid"))) -> Missing | R20: =IF(E20="","Missing",IF(COUNTIF($E$2:$E$207,E20)>1,"Duplicate",IF(AND(LEN(E20)=16,LEFT(E20,5)="+63 9"),"Valid","Check"))) -> Valid | S20: =IF(AND(Q20="Valid",R20="Valid",N20<>""),"Complete","Needs follow-up") -> Needs follow-up | T20: R228
A21: BHG-10020 | B21: Queenie | C21: Lualhati | D21: queenie.lualhati@example.com | E21: +63 945 555 3327 | F21: Iriga City | G21: Camarines Sur | H21: POS | I21: 45153 | J21: 46092 | K21: 4 | L21: 4300 | M21: =IFERROR(L21/K21,0) -> 1075 | N21: No | O21: =IF(J21="","",AsOfDate-J21) -> 203 | P21: =IF(A21="","",IF(AsOfDate-I21<=90,"New",IF(AND(O21<=180,L21>=15000),"VIP",IF(O21<=180,"Regular",IF(O21<=365,"At risk","Lapsed"))))) -> At risk | Q21: =IF(D21="","Missing",IF(COUNTIF($D$2:$D$207,D21)>1,"Duplicate",IF(AND(LEN(D21)-LEN(SUBSTITUTE(D21,"@",""))=1,ISNUMBER(SEARCH(".",D21,SEARCH("@",D21))),ISERROR(SEARCH(" ",D21))),"Valid","Invalid"))) -> Valid | R21: =IF(E21="","Missing",IF(COUNTIF($E$2:$E$207,E21)>1,"Duplicate",IF(AND(LEN(E21)=16,LEFT(E21,5)="+63 9"),"Valid","Check"))) -> Valid | S21: =IF(AND(Q21="Valid",R21="Valid",N21<>""),"Complete","Needs follow-up") -> Complete | T21: R242
A22: BHG-10021 | B22: Jerome | C22: Ocampo | D22: jerome.ocampo@mail.example.com | E22: +63 927 555 4463 | F22: Naga City | G22: Camarines Sur | H22: WEB + POS | I22: 45154 | J22: 46020 | K22: 7 | L22: 6620 | M22: =IFERROR(L22/K22,0) -> 945.71429 | N22: No | O22: =IF(J22="","",AsOfDate-J22) -> 275 | P22: =IF(A22="","",IF(AsOfDate-I22<=90,"New",IF(AND(O22<=180,L22>=15000),"VIP",IF(O22<=180,"Regular",IF(O22<=365,"At risk","Lapsed"))))) -> At risk | Q22: =IF(D22="","Missing",IF(COUNTIF($D$2:$D$207,D22)>1,"Duplicate",IF(AND(LEN(D22)-LEN(SUBSTITUTE(D22,"@",""))=1,ISNUMBER(SEARCH(".",D22,SEARCH("@",D22))),ISERROR(SEARCH(" ",D22))),"Valid","Invalid"))) -> Valid | R22: =IF(E22="","Missing",IF(COUNTIF($E$2:$E$207,E22)>1,"Duplicate",IF(AND(LEN(E22)=16,LEFT(E22,5)="+63 9"),"Valid","Check"))) -> Valid | S22: =IF(AND(Q22="Valid",R22="Valid",N22<>""),"Complete","Needs follow-up") -> Complete | T22: R086, R226
A23: BHG-10022 | B23: Sarah | C23: Pascual | D23: sarah.pascual@mail.example.com | E23: +63 998 555 7907 | F23: Daet | G23: Camarines Norte | H23: POS | I23: 45167 | J23: 46091 | K23: 7 | L23: 4580 | M23: =IFERROR(L23/K23,0) -> 654.28571 | N23: Yes | O23: =IF(J23="","",AsOfDate-J23) -> 204 | P23: =IF(A23="","",IF(AsOfDate-I23<=90,"New",IF(AND(O23<=180,L23>=15000),"VIP",IF(O23<=180,"Regular",IF(O23<=365,"At risk","Lapsed"))))) -> At risk | Q23: =IF(D23="","Missing",IF(COUNTIF($D$2:$D$207,D23)>1,"Duplicate",IF(AND(LEN(D23)-LEN(SUBSTITUTE(D23,"@",""))=1,ISNUMBER(SEARCH(".",D23,SEARCH("@",D23))),ISERROR(SEARCH(" ",D23))),"Valid","Invalid"))) -> Valid | R23: =IF(E23="","Missing",IF(COUNTIF($E$2:$E$207,E23)>1,"Duplicate",IF(AND(LEN(E23)=16,LEFT(E23,5)="+63 9"),"Valid","Check"))) -> Valid | S23: =IF(AND(Q23="Valid",R23="Valid",N23<>""),"Complete","Needs follow-up") -> Complete | T23: R243
A24: BHG-10023 | B24: Ivan | C24: Navarro | D24: ivan.navarro@example.com | E24: +63 918 555 8417 | F24: Sorsogon City | G24: Sorsogon | H24: FB | I24: 45171 | J24: 46064 | K24: 5 | L24: 7960 | M24: =IFERROR(L24/K24,0) -> 1592 | O24: =IF(J24="","",AsOfDate-J24) -> 231 | P24: =IF(A24="","",IF(AsOfDate-I24<=90,"New",IF(AND(O24<=180,L24>=15000),"VIP",IF(O24<=180,"Regular",IF(O24<=365,"At risk","Lapsed"))))) -> At risk | Q24: =IF(D24="","Missing",IF(COUNTIF($D$2:$D$207,D24)>1,"Duplicate",IF(AND(LEN(D24)-LEN(SUBSTITUTE(D24,"@",""))=1,ISNUMBER(SEARCH(".",D24,SEARCH("@",D24))),ISERROR(SEARCH(" ",D24))),"Valid","Invalid"))) -> Valid | R24: =IF(E24="","Missing",IF(COUNTIF($E$2:$E$207,E24)>1,"Duplicate",IF(AND(LEN(E24)=16,LEFT(E24,5)="+63 9"),"Valid","Check"))) -> Valid | S24: =IF(AND(Q24="Valid",R24="Valid",N24<>""),"Complete","Needs follow-up") -> Needs follow-up | T24: R118
A25: BHG-10024 | B25: Odette | C25: Gonzales | D25: odette.gonzales@example.org | E25: +63 954 555 6686 | F25: Pili | G25: Camarines Sur | H25: WEB | I25: 45175 | J25: 45974 | K25: 9 | L25: 11010 | M25: =IFERROR(L25/K25,0) -> 1223.3333 | N25: Yes | O25: =IF(J25="","",AsOfDate-J25) -> 321 | P25: =IF(A25="","",IF(AsOfDate-I25<=90,"New",IF(AND(O25<=180,L25>=15000),"VIP",IF(O25<=180,"Regular",IF(O25<=365,"At risk","Lapsed"))))) -> At risk | Q25: =IF(D25="","Missing",IF(COUNTIF($D$2:$D$207,D25)>1,"Duplicate",IF(AND(LEN(D25)-LEN(SUBSTITUTE(D25,"@",""))=1,ISNUMBER(SEARCH(".",D25,SEARCH("@",D25))),ISERROR(SEARCH(" ",D25))),"Valid","Invalid"))) -> Valid | R25: =IF(E25="","Missing",IF(COUNTIF($E$2:$E$207,E25)>1,"Duplicate",IF(AND(LEN(E25)=16,LEFT(E25,5)="+63 9"),"Valid","Check"))) -> Valid | S25: =IF(AND(Q25="Valid",R25="Valid",N25<>""),"Complete","Needs follow-up") -> Complete | T25: R078
A26: BHG-10025 | B26: Tristan | C26: Morales | D26: tristan.morales@example.com | E26: +63 998 555 6749 | F26: Virac | G26: Catanduanes | H26: WEB | I26: 45175 | J26: 45955 | K26: 8 | L26: 5520 | M26: =IFERROR(L26/K26,0) -> 690 | N26: Yes | O26: =IF(J26="","",AsOfDate-J26) -> 340 | P26: =IF(A26="","",IF(AsOfDate-I26<=90,"New",IF(AND(O26<=180,L26>=15000),"VIP",IF(O26<=180,"Regular",IF(O26<=365,"At risk","Lapsed"))))) -> At risk | Q26: =IF(D26="","Missing",IF(COUNTIF($D$2:$D$207,D26)>1,"Duplicate",IF(AND(LEN(D26)-LEN(SUBSTITUTE(D26,"@",""))=1,ISNUMBER(SEARCH(".",D26,SEARCH("@",D26))),ISERROR(SEARCH(" ",D26))),"Valid","Invalid"))) -> Valid | R26: =IF(E26="","Missing",IF(COUNTIF($E$2:$E$207,E26)>1,"Duplicate",IF(AND(LEN(E26)=16,LEFT(E26,5)="+63 9"),"Valid","Check"))) -> Valid | S26: =IF(AND(Q26="Valid",R26="Valid",N26<>""),"Complete","Needs follow-up") -> Complete | T26: R040
A27: BHG-10026 | B27: Edwin | C27: Valdez | D27: edwin.valdez@example.com | E27: +63 928 555 4401 | F27: Naga City | G27: Camarines Sur | H27: WEB | I27: 45176 | J27: 46194 | K27: 14 | L27: 22620 | M27: =IFERROR(L27/K27,0) -> 1615.7143 | N27: Yes | O27: =IF(J27="","",AsOfDate-J27) -> 101 | P27: =IF(A27="","",IF(AsOfDate-I27<=90,"New",IF(AND(O27<=180,L27>=15000),"VIP",IF(O27<=180,"Regular",IF(O27<=365,"At risk","Lapsed"))))) -> VIP | Q27: =IF(D27="","Missing",IF(COUNTIF($D$2:$D$207,D27)>1,"Duplicate",IF(AND(LEN(D27)-LEN(SUBSTITUTE(D27,"@",""))=1,ISNUMBER(SEARCH(".",D27,SEARCH("@",D27))),ISERROR(SEARCH(" ",D27))),"Valid","Invalid"))) -> Valid | R27: =IF(E27="","Missing",IF(COUNTIF($E$2:$E$207,E27)>1,"Duplicate",IF(AND(LEN(E27)=16,LEFT(E27,5)="+63 9"),"Valid","Check"))) -> Valid | S27: =IF(AND(Q27="Valid",R27="Valid",N27<>""),"Complete","Needs follow-up") -> Complete | T27: R003
A28: BHG-10027 | B28: Precious | C28: Nolasco | D28: precious.nolasco@example.com | E28: +63 918 555 0963 | F28: Daraga | G28: Albay | H28: FB | I28: 45176 | J28: 46166 | K28: 8 | L28: 11660 | M28: =IFERROR(L28/K28,0) -> 1457.5 | N28: No | O28: =IF(J28="","",AsOfDate-J28) -> 129 | P28: =IF(A28="","",IF(AsOfDate-I28<=90,"New",IF(AND(O28<=180,L28>=15000),"VIP",IF(O28<=180,"Regular",IF(O28<=365,"At risk","Lapsed"))))) -> Regular | Q28: =IF(D28="","Missing",IF(COUNTIF($D$2:$D$207,D28)>1,"Duplicate",IF(AND(LEN(D28)-LEN(SUBSTITUTE(D28,"@",""))=1,ISNUMBER(SEARCH(".",D28,SEARCH("@",D28))),ISERROR(SEARCH(" ",D28))),"Valid","Invalid"))) -> Valid | R28: =IF(E28="","Missing",IF(COUNTIF($E$2:$E$207,E28)>1,"Duplicate",IF(AND(LEN(E28)=16,LEFT(E28,5)="+63 9"),"Valid","Check"))) -> Valid | S28: =IF(AND(Q28="Valid",R28="Valid",N28<>""),"Complete","Needs follow-up") -> Complete | T28: R110
A29: BHG-10028 | B29: Cedric | C29: De Leon | D29: cedric.deleon@mail.example.com | E29: +63 919 555 3704 | F29: Legazpi City | G29: Albay | H29: WEB + FB | I29: 45180 | J29: 46072 | K29: 8 | L29: 10880 | M29: =IFERROR(L29/K29,0) -> 1360 | N29: No | O29: =IF(J29="","",AsOfDate-J29) -> 223 | P29: =IF(A29="","",IF(AsOfDate-I29<=90,"New",IF(AND(O29<=180,L29>=15000),"VIP",IF(O29<=180,"Regular",IF(O29<=365,"At risk","Lapsed"))))) -> At risk | Q29: =IF(D29="","Missing",IF(COUNTIF($D$2:$D$207,D29)>1,"Duplicate",IF(AND(LEN(D29)-LEN(SUBSTITUTE(D29,"@",""))=1,ISNUMBER(SEARCH(".",D29,SEARCH("@",D29))),ISERROR(SEARCH(" ",D29))),"Valid","Invalid"))) -> Valid | R29: =IF(E29="","Missing",IF(COUNTIF($E$2:$E$207,E29)>1,"Duplicate",IF(AND(LEN(E29)=16,LEFT(E29,5)="+63 9"),"Valid","Check"))) -> Valid | S29: =IF(AND(Q29="Valid",R29="Valid",N29<>""),"Complete","Needs follow-up") -> Complete | T29: R097, R185
A30: BHG-10029 | B30: Edwin | C30: Tolentino | E30: +63 995 555 6521 | F30: Naga City | G30: Camarines Sur | H30: FB | I30: 45181 | J30: 46058 | K30: 4 | L30: 4230 | M30: =IFERROR(L30/K30,0) -> 1057.5 | N30: Yes | O30: =IF(J30="","",AsOfDate-J30) -> 237 | P30: =IF(A30="","",IF(AsOfDate-I30<=90,"New",IF(AND(O30<=180,L30>=15000),"VIP",IF(O30<=180,"Regular",IF(O30<=365,"At risk","Lapsed"))))) -> At risk | Q30: =IF(D30="","Missing",IF(COUNTIF($D$2:$D$207,D30)>1,"Duplicate",IF(AND(LEN(D30)-LEN(SUBSTITUTE(D30,"@",""))=1,ISNUMBER(SEARCH(".",D30,SEARCH("@",D30))),ISERROR(SEARCH(" ",D30))),"Valid","Invalid"))) -> Missing | R30: =IF(E30="","Missing",IF(COUNTIF($E$2:$E$207,E30)>1,"Duplicate",IF(AND(LEN(E30)=16,LEFT(E30,5)="+63 9"),"Valid","Check"))) -> Valid | S30: =IF(AND(Q30="Valid",R30="Valid",N30<>""),"Complete","Needs follow-up") -> Needs follow-up | T30: R172
A31: BHG-10030 | B31: Tristan | C31: Sison | D31: tristan.sison@example.org | E31: +63 954 555 1403 | F31: Masbate City | G31: Masbate | H31: WEB | I31: 45183 | J31: 46286 | K31: 22 | L31: 28050 | M31: =IFERROR(L31/K31,0) -> 1275 | N31: Yes | O31: =IF(J31="","",AsOfDate-J31) -> 9 | P31: =IF(A31="","",IF(AsOfDate-I31<=90,"New",IF(AND(O31<=180,L31>=15000),"VIP",IF(O31<=180,"Regular",IF(O31<=365,"At risk","Lapsed"))))) -> VIP | Q31: =IF(D31="","Missing",IF(COUNTIF($D$2:$D$207,D31)>1,"Duplicate",IF(AND(LEN(D31)-LEN(SUBSTITUTE(D31,"@",""))=1,ISNUMBER(SEARCH(".",D31,SEARCH("@",D31))),ISERROR(SEARCH(" ",D31))),"Valid","Invalid"))) -> Valid | R31: =IF(E31="","Missing",IF(COUNTIF($E$2:$E$207,E31)>1,"Duplicate",IF(AND(LEN(E31)=16,LEFT(E31,5)="+63 9"),"Valid","Check"))) -> Valid | S31: =IF(AND(Q31="Valid",R31="Valid",N31<>""),"Complete","Needs follow-up") -> Complete | T31: R002
A32: BHG-10031 | B32: Xander | C32: Torres | D32: xander.torres@example.com | E32: +63 995 555 6206 | F32: Naga City | G32: Camarines Sur | H32: FB | I32: 45190 | J32: 45858 | K32: 2 | L32: 2460 | M32: =IFERROR(L32/K32,0) -> 1230 | N32: Yes | O32: =IF(J32="","",AsOfDate-J32) -> 437 | P32: =IF(A32="","",IF(AsOfDate-I32<=90,"New",IF(AND(O32<=180,L32>=15000),"VIP",IF(O32<=180,"Regular",IF(O32<=365,"At risk","Lapsed"))))) -> Lapsed | Q32: =IF(D32="","Missing",IF(COUNTIF($D$2:$D$207,D32)>1,"Duplicate",IF(AND(LEN(D32)-LEN(SUBSTITUTE(D32,"@",""))=1,ISNUMBER(SEARCH(".",D32,SEARCH("@",D32))),ISERROR(SEARCH(" ",D32))),"Valid","Invalid"))) -> Valid | R32: =IF(E32="","Missing",IF(COUNTIF($E$2:$E$207,E32)>1,"Duplicate",IF(AND(LEN(E32)=16,LEFT(E32,5)="+63 9"),"Valid","Check"))) -> Valid | S32: =IF(AND(Q32="Valid",R32="Valid",N32<>""),"Complete","Needs follow-up") -> Complete | T32: R126
A33: BHG-10032 | B33: Wendy | C33: Tan | D33: wendy.tan@example.com | E33: +63 928 555 3453 | F33: Naga City | G33: Camarines Sur | H33: WEB | I33: 45196 | J33: 46237 | K33: 8 | L33: 7990 | M33: =IFERROR(L33/K33,0) -> 998.75 | N33: Yes | O33: =IF(J33="","",AsOfDate-J33) -> 58 | P33: =IF(A33="","",IF(AsOfDate-I33<=90,"New",IF(AND(O33<=180,L33>=15000),"VIP",IF(O33<=180,"Regular",IF(O33<=365,"At risk","Lapsed"))))) -> Regular | Q33: =IF(D33="","Missing",IF(COUNTIF($D$2:$D$207,D33)>1,"Duplicate",IF(AND(LEN(D33)-LEN(SUBSTITUTE(D33,"@",""))=1,ISNUMBER(SEARCH(".",D33,SEARCH("@",D33))),ISERROR(SEARCH(" ",D33))),"Valid","Invalid"))) -> Valid | R33: =IF(E33="","Missing",IF(COUNTIF($E$2:$E$207,E33)>1,"Duplicate",IF(AND(LEN(E33)=16,LEFT(E33,5)="+63 9"),"Valid","Check"))) -> Valid | S33: =IF(AND(Q33="Valid",R33="Valid",N33<>""),"Complete","Needs follow-up") -> Complete | T33: R063
A34: BHG-10033 | B34: Wendy | C34: Dimaculangan | D34: wendy.dimaculangan@example.com | E34: +63 928 555 6822 | F34: Naga City | G34: Camarines Sur | H34: FB + POS | I34: 45197 | J34: 45619 | K34: 5 | L34: 4580 | M34: =IFERROR(L34/K34,0) -> 916 | N34: No | O34: =IF(J34="","",AsOfDate-J34) -> 676 | P34: =IF(A34="","",IF(AsOfDate-I34<=90,"New",IF(AND(O34<=180,L34>=15000),"VIP",IF(O34<=180,"Regular",IF(O34<=365,"At risk","Lapsed"))))) -> Lapsed | Q34: =IF(D34="","Missing",IF(COUNTIF($D$2:$D$207,D34)>1,"Duplicate",IF(AND(LEN(D34)-LEN(SUBSTITUTE(D34,"@",""))=1,ISNUMBER(SEARCH(".",D34,SEARCH("@",D34))),ISERROR(SEARCH(" ",D34))),"Valid","Invalid"))) -> Valid | R34: =IF(E34="","Missing",IF(COUNTIF($E$2:$E$207,E34)>1,"Duplicate",IF(AND(LEN(E34)=16,LEFT(E34,5)="+63 9"),"Valid","Check"))) -> Valid | S34: =IF(AND(Q34="Valid",R34="Valid",N34<>""),"Complete","Needs follow-up") -> Complete | T34: R167, R257
A35: BHG-10034 | B35: Mark | C35: Gonzales | D35: mark.gonzales@example.com | E35: +63 945 555 2257 | F35: Sorsogon City | G35: Sorsogon | H35: FB | I35: 45203 | J35: 46208 | K35: 8 | L35: 7450 | M35: =IFERROR(L35/K35,0) -> 931.25 | N35: No | O35: =IF(J35="","",AsOfDate-J35) -> 87 | P35: =IF(A35="","",IF(AsOfDate-I35<=90,"New",IF(AND(O35<=180,L35>=15000),"VIP",IF(O35<=180,"Regular",IF(O35<=365,"At risk","Lapsed"))))) -> Regular | Q35: =IF(D35="","Missing",IF(COUNTIF($D$2:$D$207,D35)>1,"Duplicate",IF(AND(LEN(D35)-LEN(SUBSTITUTE(D35,"@",""))=1,ISNUMBER(SEARCH(".",D35,SEARCH("@",D35))),ISERROR(SEARCH(" ",D35))),"Valid","Invalid"))) -> Valid | R35: =IF(E35="","Missing",IF(COUNTIF($E$2:$E$207,E35)>1,"Duplicate",IF(AND(LEN(E35)=16,LEFT(E35,5)="+63 9"),"Valid","Check"))) -> Valid | S35: =IF(AND(Q35="Valid",R35="Valid",N35<>""),"Complete","Needs follow-up") -> Complete | T35: R134
A36: BHG-10035 | B36: Oscar | C36: Quiambao | D36: oscar.quiambao@example.net | E36: +63 928 555 5585 | F36: Tabaco City | G36: Albay | H36: FB + POS | I36: 45205 | J36: 46079 | K36: 6 | L36: 9220 | M36: =IFERROR(L36/K36,0) -> 1536.6667 | N36: Yes | O36: =IF(J36="","",AsOfDate-J36) -> 216 | P36: =IF(A36="","",IF(AsOfDate-I36<=90,"New",IF(AND(O36<=180,L36>=15000),"VIP",IF(O36<=180,"Regular",IF(O36<=365,"At risk","Lapsed"))))) -> At risk | Q36: =IF(D36="","Missing",IF(COUNTIF($D$2:$D$207,D36)>1,"Duplicate",IF(AND(LEN(D36)-LEN(SUBSTITUTE(D36,"@",""))=1,ISNUMBER(SEARCH(".",D36,SEARCH("@",D36))),ISERROR(SEARCH(" ",D36))),"Valid","Invalid"))) -> Valid | R36: =IF(E36="","Missing",IF(COUNTIF($E$2:$E$207,E36)>1,"Duplicate",IF(AND(LEN(E36)=16,LEFT(E36,5)="+63 9"),"Valid","Check"))) -> Valid | S36: =IF(AND(Q36="Valid",R36="Valid",N36<>""),"Complete","Needs follow-up") -> Complete | T36: R125, R192
A37: BHG-10036 | B37: Zaldy | C37: Obsuna | D37: zaldy.obsuna@example.com | E37: +63 961 555 1192 | F37: Legazpi City | G37: Albay | H37: WEB | I37: 45206 | J37: 46177 | K37: 17 | L37: 21010 | M37: =IFERROR(L37/K37,0) -> 1235.8824 | N37: No | O37: =IF(J37="","",AsOfDate-J37) -> 118 | P37: =IF(A37="","",IF(AsOfDate-I37<=90,"New",IF(AND(O37<=180,L37>=15000),"VIP",IF(O37<=180,"Regular",IF(O37<=365,"At risk","Lapsed"))))) -> VIP | Q37: =IF(D37="","Missing",IF(COUNTIF($D$2:$D$207,D37)>1,"Duplicate",IF(AND(LEN(D37)-LEN(SUBSTITUTE(D37,"@",""))=1,ISNUMBER(SEARCH(".",D37,SEARCH("@",D37))),ISERROR(SEARCH(" ",D37))),"Valid","Invalid"))) -> Valid | R37: =IF(E37="","Missing",IF(COUNTIF($E$2:$E$207,E37)>1,"Duplicate",IF(AND(LEN(E37)=16,LEFT(E37,5)="+63 9"),"Valid","Check"))) -> Valid | S37: =IF(AND(Q37="Valid",R37="Valid",N37<>""),"Complete","Needs follow-up") -> Complete | T37: R028
A38: BHG-10037 | B38: Mia | C38: Fernandez | D38: mia.fernandez@example.com | E38: +63 927 555 4680 | F38: Naga City | G38: Camarines Sur | H38: POS | I38: 45212 | J38: 46181 | K38: 15 | L38: 24400 | M38: =IFERROR(L38/K38,0) -> 1626.6667 | N38: Yes | O38: =IF(J38="","",AsOfDate-J38) -> 114 | P38: =IF(A38="","",IF(AsOfDate-I38<=90,"New",IF(AND(O38<=180,L38>=15000),"VIP",IF(O38<=180,"Regular",IF(O38<=365,"At risk","Lapsed"))))) -> VIP | Q38: =IF(D38="","Missing",IF(COUNTIF($D$2:$D$207,D38)>1,"Duplicate",IF(AND(LEN(D38)-LEN(SUBSTITUTE(D38,"@",""))=1,ISNUMBER(SEARCH(".",D38,SEARCH("@",D38))),ISERROR(SEARCH(" ",D38))),"Valid","Invalid"))) -> Valid | R38: =IF(E38="","Missing",IF(COUNTIF($E$2:$E$207,E38)>1,"Duplicate",IF(AND(LEN(E38)=16,LEFT(E38,5)="+63 9"),"Valid","Check"))) -> Valid | S38: =IF(AND(Q38="Valid",R38="Valid",N38<>""),"Complete","Needs follow-up") -> Complete | T38: R237
A39: BHG-10038 | B39: Rodel | C39: Sison | D39: rodel.sison@example.net | E39: +63 945 555 2777 | F39: Daet | G39: Camarines Norte | H39: WEB | I39: 45214 | J39: 46092 | K39: 5 | L39: 7020 | M39: =IFERROR(L39/K39,0) -> 1404 | N39: Yes | O39: =IF(J39="","",AsOfDate-J39) -> 203 | P39: =IF(A39="","",IF(AsOfDate-I39<=90,"New",IF(AND(O39<=180,L39>=15000),"VIP",IF(O39<=180,"Regular",IF(O39<=365,"At risk","Lapsed"))))) -> At risk | Q39: =IF(D39="","Missing",IF(COUNTIF($D$2:$D$207,D39)>1,"Duplicate",IF(AND(LEN(D39)-LEN(SUBSTITUTE(D39,"@",""))=1,ISNUMBER(SEARCH(".",D39,SEARCH("@",D39))),ISERROR(SEARCH(" ",D39))),"Valid","Invalid"))) -> Valid | R39: =IF(E39="","Missing",IF(COUNTIF($E$2:$E$207,E39)>1,"Duplicate",IF(AND(LEN(E39)=16,LEFT(E39,5)="+63 9"),"Valid","Check"))) -> Valid | S39: =IF(AND(Q39="Valid",R39="Valid",N39<>""),"Complete","Needs follow-up") -> Complete | T39: R094
A40: BHG-10039 | B40: Carlo | C40: Rivera | D40: carlo.rivera@example.com | E40: +63 920 555 0814 | F40: Legazpi City | G40: Albay | H40: FB | I40: 45225 | J40: 46093 | K40: 6 | L40: 5540 | M40: =IFERROR(L40/K40,0) -> 923.33333 | N40: Yes | O40: =IF(J40="","",AsOfDate-J40) -> 202 | P40: =IF(A40="","",IF(AsOfDate-I40<=90,"New",IF(AND(O40<=180,L40>=15000),"VIP",IF(O40<=180,"Regular",IF(O40<=365,"At risk","Lapsed"))))) -> At risk | Q40: =IF(D40="","Missing",IF(COUNTIF($D$2:$D$207,D40)>1,"Duplicate",IF(AND(LEN(D40)-LEN(SUBSTITUTE(D40,"@",""))=1,ISNUMBER(SEARCH(".",D40,SEARCH("@",D40))),ISERROR(SEARCH(" ",D40))),"Valid","Invalid"))) -> Valid | R40: =IF(E40="","Missing",IF(COUNTIF($E$2:$E$207,E40)>1,"Duplicate",IF(AND(LEN(E40)=16,LEFT(E40,5)="+63 9"),"Valid","Check"))) -> Valid | S40: =IF(AND(Q40="Valid",R40="Valid",N40<>""),"Complete","Needs follow-up") -> Complete | T40: R114
...

Sheet Raw Combined
A1: Raw Row | B1: Source | C1: Source Ref | D1: Full Name | E1: Email | F1: Mobile | G1: City | H1: Province | I1: First Order | J1: Last Order | K1: Orders | L1: Total Spent | M1: Marketing Consent
A2: R001 | B2: WEB | C2: WEB-20413 | D2: Cathy Villanueva | E2: cathy.villanueva@example.com | F2: 09195559670 | G2: IRIGA CITY | H2: Camarines Sur | I2: 2024-03-06 | J2: 2026-07-18 | K2: 3 | L2: 4350.00 | M2: TRUE
A3: R002 | B3: WEB | C3: WEB-20415 | D3: Tristan Sison | E3: tristan.sison@example.org | F3: 09545551403 | G3: Masbate City | H3: Masbate | I3: 2023-09-14 | J3: 2026-09-21 | K3: 22 | L3: 28050.00 | M3: TRUE
A4: R003 | B4: WEB | C4: WEB-20418 | D4: Edwin Valdez | E4: edwin.valdez@example.com | F4: 09285554401 | G4: Naga City | H4: Camarines Sur | I4: 2023-09-07 | J4: 2026-06-21 | K4: 14 | L4: 22620.00 | M4: TRUE
A5: R004 | B5: WEB | C5: WEB-20419 | D5: Tonette Castillo | E5: tonette.castillo@example.com | F5: 09285554774 | G5: Naga City | H5: Camarines Sur | I5: 2024-12-10 | J5: 2026-02-03 | K5: 2 | L5: 1770.00 | M5: FALSE
A6: R005 | B6: WEB | C6: WEB-20422 | D6: Jomar Cruz | E6: jomar.cruz@example.net | F6: 09175554023 | G6: Naga City | H6: CAM. SUR | I6: 2023-06-16 | J6: 2024-05-27 | K6: 1 | L6: 1780.00 | M6: TRUE
A7: R006 | B7: WEB | C7: WEB-20423 | D7: Miguel Cruz | E7: miguel.cruz@example.com | F7: +639195556778 | G7: VIRAC | H7: Catanduanes | I7: 2025-02-19 | J7: 2026-07-19 | K7: 6 | L7: 11070.00 | M7: TRUE
A8: R007 | B8: WEB | C8: WEB-20425 | D8: Tess Manalo | E8: Tess.manalo@mail.example.com | F8: +63 998 555 0205 | G8: Masbate City | H8: masbate | I8: 2024-02-21 | J8: 2025-02-15 | K8: 23 | L8: 35990.00 | M8: TRUE
A9: R008 | B9: WEB | C9: WEB-20429 | D9: Sarah Hidalgo | E9: sarah.hidalgo@example.com | F9: +63 954 555 7452 | G9: Buhi | H9: CamSur | I9: 2024-05-26 | J9: 2026-08-24 | K9: 7 | L9: 5830.00 | M9: TRUE
A10: R009 | B10: WEB | C10: WEB-20433 | D10: Pauline Cruz | E10: pauline.cruz@exmaple.com | F10: +639985558552 | G10: NAGA | H10: Cam Sur | I10: 2023-07-15 | J10: 2023-07-15 | K10: 1 | L10: 920.00 | M10: TRUE
A11: R010 | B11: WEB | C11: WEB-20434 | D11: Clara Lualhati | E11: clualhati44@example.com | F11: 09545552028 | G11: legaspi city | H11: Albay | I11: 2024-02-23 | J11: 2026-06-12 | K11: 11 | L11: 19740.00 | M11: FALSE
A12: R011 | B12: WEB | C12: WEB-20438 | D12: Leo Valdez | E12: lvaldez94@example.org | F12: 09275552161 | G12: BUHI | H12: Camarines Sur | I12: 2025-02-19 | J12: 2025-06-20 | K12: 3 | L12: 3290.00 | M12: FALSE
... A110: R109 | B110: WEB | C110: WEB-20696 | D110: Mark Dizon | E110: mark.dizon@example.com | F110: +639455556838 | G110: NAGA | H110: Camarines Sur | I110: 2023-11-26 | J110: 2023-11-26 | K110: 1 | L110: 930.00 | M110: TRUE
A111: R110 | B111: FB | C111: FB-0313 | D111: Precious Nolasco | E111: precious.nolasco@example.com | F111: (0918) 555-0963 | G111: DARAGA | I111: 07-Sep-2023 | J111: 24-May-2026 | K111: 8 orders | L111: ₱11,660 | M111: no
A112: R111 | B112: FB | C112: FB-0316 | D112: Hannah Ocampo | E112: hannah.ocampo@example.net | F112: (0945) 555-1293 | G112: Naga | H112: Camarines Sur | I112: August 23 2026 | J112: Sep 1, 2026 | K112: 1 | L112: 770 | M112: No
A113: R112 | B113: FB | C113: FB-0319 | D113: Bernadette Cabrera | E113: bernadette.cabrera@example.com | F113: 09395557626 | G113: Naga City | H113: CAM. SUR | I113: April 28 2025 | J113: 19-Aug-2026 | K113: 10 orders | L113: 9,860 | M113: yes
A114: R113 | B114: FB | C114: FB-0322 | D114: gerald salazar | E114: GERALD.SALAZAR@EXAMPLE.NET | F114: 0919 555 3247 | G114: naga city | I114: Jul 25, 2026 | J114: July 25 2026 | K114: 1 | L114: P1,330.00 | M114: yes
A115: R114 | B115: FB | C115: FB-0325 | D115: Carlo Rivera | E115: carlo.rivera@example.com | F115: 920 555 0814 | G115: legaspi city | H115: Albay | I115: Oct 26, 2023 | J115: Mar 12, 2026 | K115: 6 orders | L115: 5,540 | M115: Y
A116: R115 | B116: FB | C116: FB-0326 | D116: jessa mendoza | F116: 0977 555 0698 | G116: Naga City | H116: Camarines Sur | I116: Aug 3, 2024 | J116: October 14 2025 | K116: 1 | L116: P1,280.00 | M116: no
A117: R116 | B117: FB | C117: FB-0330 | D117: Cathy Flores | E117: cathy.flores@example.com | F117: 0920 555 4882 | G117: SORSOGON CITY | H117: Sorsogon | I117: May 2 2025 | J117: Aug 17, 2026 | K117: 6 orders | L117: P10,020.00 | M117: yes
A118: R117 | B118: FB | C118: FB-0334 | D118: Alvin Dela Cruz | E118: alvin.delacruz@example.com | F118: 995 555 7735 | G118: daraga | H118: ALBAY | I118: Nov 10, 2024 | J118: January 20 2026 | K118: 9 | L118: P7,390.00
A119: R118 | B119: FB | C119: FB-0338 | D119: ivan navarro | E119: ivan.navarro@example.com | F119: 09185558417 | G119: Sorsogon City | H119: Sorsogon | I119: September 2 2023 | J119: Feb 11, 2026 | K119: 5 orders | L119: ₱7,960
A120: R119 | B120: FB | C120: FB-0342 | D120: dan yap | E120: dan.yap@example.net | F120: 0945 555 1875 | G120: VIRAC | H120: CATANDUANES | I120: 08-Nov-2024 | J120: Oct 23, 2025 | K120: 9 orders | L120: 15,840 | M120: no
A121: R120 | B121: FB | C121: FB-0346 | D121: marvin torres | E121: marvin.torres@example.com | F121: 0998 555 8961 | G121: Naga city | H121: Camarines Sur | I121: Apr 5, 2024 | J121: Sep 27, 2024 | K121: 5 | L121: 4,740 | M121: yes
A122: R121 | B122: FB | C122: FB-0350 | D122: ben castillo | E122: ben.castillo@example.com | F122: 09455559269 | G122: Naga City | H122: Camarines Sur | I122: 20-Aug-2026 | J122: August 20 2026 | K122: 1 order | L122: P970.00 | M122: yes
A123: R122 | B123: FB | C123: FB-0352 | D123: patrick valdez | E123: patrick.valdez@example.net | F123: 998 555 5222 | G123: Naga City | I123: August 10 2024 | J123: 18-Jul-2026 | K123: 29 | L123: ₱40,540 | M123: Yes
A124: R123 | B124: FB | C124: FB-0354 | D124: aira santiago | E124: aira.santiago@example.com | F124: 918 555 8391 | G124: Naga City | H124: Camarines Sur | I124: Jul 8, 2023 | J124: January 10 2024 | K124: 4 | L124: P7,510.00 | M124: no
A125: R124 | B125: FB | C125: FB-0358 | D125: Hector Ordonez | E125: hector.ordonez@example.com | F125: (0919) 555-4423 | G125: Iriga | H125: Camarines Sur | I125: June 9 2024 | J125: July 27 2026 | K125: 12 | L125: ₱19,560
A126: R125 | B126: FB | C126: FB-0360 | D126: oscar quiambao | E126: oscar.quiambao@example.net | F126: (0928) 555-5585 | G126: Tabaco City | H126: Albay | I126: Oct 6, 2023 | J126: September 19 2024 | K126: 4 | L126: 6,150 | M126: yes
A127: R126 | B127: FB | C127: FB-0363 | D127: Xander Torres | E127: xander.torres@example.com | F127: 995 555 6206 | G127: Naga City | H127: Camarines Sur | I127: September 21 2023 | J127: Jul 20, 2025 | K127: 2 | L127: 2,460 | M127: Y
A128: R127 | B128: FB | C128: FB-0364 | D128: Fritz Francisco | E128: ffrancisco45@example.com | F128: 09615553755 | G128: DARAGA | H128: Albay | I128: 06-Mar-2023 | J128: 13-Jun-2025 | K128: 2 | L128: 3,390
A129: R128 | B129: FB | C129: FB-0367 | D129: Sam Navarro | E129: snavarro86@example.net | F129: 0917 555 4228 | G129: Sorsogon | I129: Jul 25, 2026 | J129: August 25 2026 | K129: 2 | L129: 2,100 | M129: Y
A130: R129 | B130: FB | C130: FB-0370 | D130: Zaldy Morales | E130: zaldy.morales@example.com | F130: 977 555 6014 | G130: Naga | H130: Camarines Sur | I130: 24-Nov-2023 | J130: Dec 6, 2024 | K130: 4 orders | L130: 2,920 | M130: Y
A131: R130 | B131: FB | C131: FB-0374 | D131: Rey Garcia | E131: rgarcia1@example.com | F131: 918 555 2870 | G131: Naga | I131: April 5 2024 | J131: August 15 2026 | K131: 9 | L131: P6,250.00 | M131: Y
A132: R131 | B132: FB | C132: FB-0377 | D132: Tess Manalo | E132: tess.manalo@mail.example.com | F132: 0998 555 0205 | G132: MASBATE CITY | H132: Masbate | I132: April 1 2025 | J132: 10-Aug-2026 | K132: 2 | L132: 3,130 | M132: yes
A133: R132 | B133: FB | C133: FB-0379 | D133: nico vergara | E133: nico.vergara@example.net | F133: 0918 555 4141 | G133: daraga | H133: Albay | I133: March 26 2026 | J133: May 28, 2026 | K133: 5 | L133: ₱6,930 | M133: Y
A134: R133 | B134: FB | C134: FB-0381 | D134: Venus Navarro | E134: venus.navarro | F134: 0998 555 7652 | G134: iriga | H134: Camarines Sur | I134: February 19 2025 | J134: 23-Aug-2026 | K134: 19 | L134: 23,830 | M134: Yes
A135: R134 | B135: FB | C135: FB-0382 | D135: Mark Gonzales | E135: mark.gonzales@example.com | F135: 945 555 2257 | G135: Sorsogon City | H135: Sorsogon | I135: October 4 2023 | J135: July 5 2026 | K135: 8 | L135: P7,450.00 | M135: no
A136: R135 | B136: FB | C136: FB-0386 | D136: Bryan Cruz | E136: bryan.cruz@example.com | F136: 09395550317 | G136: virac | I136: Aug 16, 2025 | J136: July 17 2026 | K136: 1 | L136: ₱1,080
A137: R136 | B137: FB | C137: FB-0390 | D137: Lorna Encarnacion | E137: lencarnacion54@mail.example.com | F137: 0995 555 1330 | G137: IRIGA CITY | H137: Camarines Sur | I137: February 1 2025 | J137: Dec 31, 2025 | K137: 7 | L137: ₱5,430 | M137: yes
...

Sheet Change Log
A1: # | B1: Raw Row | C1: Source Ref | D1: Field | E1: Before (as received) | F1: After (clean) | G1: Rule Applied
A2: 1 | B2: R001 | C2: WEB-20413 | D2: Full name | E2: Cathy Villanueva | F2: Cathy Villanueva | G2: Extra spaces removed, proper case
A3: 2 | B3: R001 | C3: WEB-20413 | D3: Mobile | E3: 09195559670 | F3: +63 919 555 9670 | G3: One format: +63 9XX XXX XXXX
A4: 3 | B4: R001 | C4: WEB-20413 | D4: City | E4: IRIGA CITY | F4: Iriga City | G4: One spelling per city
A5: 4 | B5: R001 | C5: WEB-20413 | D5: First order | E5: 2024-03-06 | F5: Mar 6, 2024 | G5: Text changed to a real date
A6: 5 | B6: R001 | C6: WEB-20413 | D6: Last order | E6: 2026-07-18 | F6: Jul 18, 2026 | G6: Text changed to a real date
A7: 6 | B7: R001 | C7: WEB-20413 | D7: Total spent | E7: 4350.00 | F7: 4350 | G7: Currency text changed to a number
A8: 7 | B8: R001 | C8: WEB-20413 | D8: Consent | E8: TRUE | F8: Yes | G8: Yes or No only
A9: 8 | B9: R002 | C9: WEB-20415 | D9: Mobile | E9: 09545551403 | F9: +63 954 555 1403 | G9: One format: +63 9XX XXX XXXX
A10: 9 | B10: R002 | C10: WEB-20415 | D10: First order | E10: 2023-09-14 | F10: Sep 14, 2023 | G10: Text changed to a real date
A11: 10 | B11: R002 | C11: WEB-20415 | D11: Last order | E11: 2026-09-21 | F11: Sep 21, 2026 | G11: Text changed to a real date
A12: 11 | B12: R002 | C12: WEB-20415 | D12: Total spent | E12: 28050.00 | F12: 28050 | G12: Currency text changed to a number
A13: 12 | B13: R002 | C13: WEB-20415 | D13: Consent | E13: TRUE | F13: Yes | G13: Yes or No only
... A1657: 1656 | B1657: R268 | C1657: POS-1372 | D1657: Consent | E1657: Y | F1657: Yes | G1657: Yes or No only

Sheet Duplicate Log
A1: Kept as | B1: Customer | C1: Raw Rows Matched | D1: Source Refs | E1: Rows | F1: Match Rule | G1: Decision
A2: BHG-10010 | B2: Jomar Cruz | C2: R005, R201 | D2: WEB-20422, POS-1204 | E2: 2 | F2: Same name and city | G2: Merged: orders and spend added, earliest first order, latest last order
A3: BHG-10054 | B3: Miguel Cruz | C3: R006, R137 | D3: WEB-20423, FB-0392 | E3: 2 | F3: Same email | G3: Merged: orders and spend added, earliest first order, latest last order
A4: BHG-10067 | B4: Tess Manalo | C4: R007, R131 | D4: WEB-20425, FB-0377 | E4: 2 | F4: Same email | G4: Merged: orders and spend added, earliest first order, latest last order
A5: BHG-10015 | B5: Pauline Cruz | C5: R009, R039 | D5: WEB-20433, WEB-20516 | E5: 2 | F5: Same email | G5: Kept once (same row exported twice)
A6: BHG-10147 | B6: Leo Valdez | C6: R011, R168 | D6: WEB-20438, FB-0466 | E6: 2 | F6: Same email | G6: Merged: orders and spend added, earliest first order, latest last order
A7: BHG-10011 | B7: Cedric Fernandez | C7: R015, R183, R245 | D7: WEB-20449, FB-0510, POS-1313 | E7: 3 | F7: Same email | G7: Merged: orders and spend added, earliest first order, latest last order
A8: BHG-10096 | B8: Sarah Soriano | C8: R017, R186 | D8: WEB-20457, FB-0517 | E8: 2 | F8: Same email | G8: Merged: orders and spend added, earliest first order, latest last order
A9: BHG-10154 | B9: Zaldy Ordonez | C9: R020, R108 | D9: WEB-20466, WEB-20692 | E9: 2 | F9: Same email | G9: Kept once (same row exported twice)
A10: BHG-10137 | B10: Wendy Cortez | C10: R021, R153, R231 | D10: WEB-20470, FB-0432, POS-1283 | E10: 3 | F10: Same email | G10: Merged: orders and spend added, earliest first order, latest last order
A11: BHG-10075 | B11: Teddy Torres | C11: R026, R154 | D11: WEB-20484, FB-0434 | E11: 2 | F11: Same email | G11: Merged: orders and spend added, earliest first order, latest last order
A12: BHG-10077 | B12: Kristine Castillo | C12: R027, R253 | D12: WEB-20485, POS-1336 | E12: 2 | F12: Same mobile number | G12: Merged: orders and spend added, earliest first order, latest last order
A13: BHG-10093 | B13: Ursula Aguilar | C13: R030, R152 | D13: WEB-20494, FB-0428 | E13: 2 | F13: Same email | G13: Merged: orders and spend added, earliest first order, latest last order
... A54: BHG-10191 | B54: Wendy Obsuna | C54: R238, R260 | D54: POS-1297, POS-1351 | E54: 2 | F54: Same email | G54: Kept once (same row exported twice)

Sheet Follow-up Queue
A1: # | B1: Customer ID | C1: Customer | D1: Segment | E1: Missing | F1: Reach Them At | G1: Next Action | H1: Owner | I1: Due | J1: Status | K1: Notes
A2: 1 | B2: BHG-10001 | C2: Fritz Francisco | D2: Lapsed | E2: Consent | F2: +63 961 555 3755 | G2: Ask if they want promos by email and SMS; record Yes or No | H2: Rose | I2: =WORKDAY(AsOfDate,IF(D2="VIP",2,IF(D2="Regular",3,5))) -> 46302 | J2: Open
A3: 2 | B3: BHG-10007 | C3: Aira Pascual | D3: At risk | E3: Mobile | F3: aira.pascual@example.com | G3: Ask for a mobile number by email | H3: Rose | I3: =WORKDAY(AsOfDate,IF(D3="VIP",2,IF(D3="Regular",3,5))) -> 46302 | J3: Open
A4: 3 | B4: BHG-10019 | C4: Ronald Nolasco | D4: VIP | E4: Email | F4: +63 961 555 8956 | G4: Ask for an email address at the next order or by SMS | H4: Rose | I4: =WORKDAY(AsOfDate,IF(D4="VIP",2,IF(D4="Regular",3,5))) -> 46297 | J4: Open
A5: 4 | B5: BHG-10023 | C5: Ivan Navarro | D5: At risk | E5: Consent | F5: +63 918 555 8417 | G5: Ask if they want promos by email and SMS; record Yes or No | H5: Rose | I5: =WORKDAY(AsOfDate,IF(D5="VIP",2,IF(D5="Regular",3,5))) -> 46302 | J5: Open
A6: 5 | B6: BHG-10029 | C6: Edwin Tolentino | D6: At risk | E6: Email | F6: +63 995 555 6521 | G6: Ask for an email address at the next order or by SMS | H6: Rose | I6: =WORKDAY(AsOfDate,IF(D6="VIP",2,IF(D6="Regular",3,5))) -> 46302 | J6: Open
A7: 6 | B7: BHG-10045 | C7: Wilma Roxas | D7: Lapsed | E7: Email | F7: +63 998 555 3127 | G7: Ask for an email address at the next order or by SMS | H7: Rose | I7: =WORKDAY(AsOfDate,IF(D7="VIP",2,IF(D7="Regular",3,5))) -> 46302 | J7: Open
A8: 7 | B8: BHG-10052 | C8: Tess Soriano | D8: At risk | E8: Email | F8: +63 954 555 2665 | G8: Ask for an email address at the next order or by SMS | H8: Rose | I8: =WORKDAY(AsOfDate,IF(D8="VIP",2,IF(D8="Regular",3,5))) -> 46302 | J8: Open
A9: 8 | B9: BHG-10055 | C9: Rica Panganiban | D9: At risk | E9: Email | F9: +63 928 555 3569 | G9: Ask for an email address at the next order or by SMS | H9: Rose | I9: =WORKDAY(AsOfDate,IF(D9="VIP",2,IF(D9="Regular",3,5))) -> 46302 | J9: Open
A10: 9 | B10: BHG-10056 | C10: Aira Lacson | D10: At risk | E10: Email | F10: +63 998 555 5918 | G10: Ask for an email address at the next order or by SMS | H10: Rose | I10: =WORKDAY(AsOfDate,IF(D10="VIP",2,IF(D10="Regular",3,5))) -> 46302 | J10: Open
A11: 10 | B11: BHG-10070 | C11: Clara Domingo | D11: VIP | E11: Email | F11: +63 945 555 5892 | G11: Ask for an email address at the next order or by SMS | H11: Rose | I11: =WORKDAY(AsOfDate,IF(D11="VIP",2,IF(D11="Regular",3,5))) -> 46297 | J11: Open
A12: 11 | B12: BHG-10082 | C12: Wendy Garcia | D12: Regular | E12: Email | F12: +63 927 555 1010 | G12: Ask for an email address at the next order or by SMS | H12: Rose | I12: =WORKDAY(AsOfDate,IF(D12="VIP",2,IF(D12="Regular",3,5))) -> 46300 | J12: Open
A13: 12 | B13: BHG-10095 | C13: Pauline Bernal | D13: Regular | E13: Email | F13: +63 928 555 3589 | G13: Ask for an email address at the next order or by SMS | H13: Rose | I13: =WORKDAY(AsOfDate,IF(D13="VIP",2,IF(D13="Regular",3,5))) -> 46300 | J13: Open
... A22: 21 | B22: BHG-10189 | C22: Mia Tan | D22: New | E22: Email | F22: +63 961 555 1469 | G22: Ask for an email address at the next order or by SMS | H22: Rose | I22: =WORKDAY(AsOfDate,IF(D22="VIP",2,IF(D22="Regular",3,5))) -> 46302 | J22: Open
B24: Due dates are set by segment: VIP in 2 working days, Regular in 3, everyone else in 5. Change Status to Done when the detail is added to Customer Master.

Sheet Data Quality
B2: Data Quality Scorecard
B3: Four standard checks, measured on the raw file at intake and live on the clean Customer Master.
B5: Check | C5: What it measures | D5: Raw file (intake) | E5: Clean list (live) | F5: Change
B6: Completeness | C6: Required fields that are filled in (name, email, mobile, city, province, dates, orders, spend, consent) | D6: 0.978 | E6: =COUNTA('Customer Master'!B2:B207,'Customer Master'!D2:G207,'Customer Master'!I2:L207,'Customer Master'!N2:N207)/(COUNTA('Customer Master'!A2:A207)*10) -> 0.98980583 | F6: =E6-D6 -> 0.011805825
B7: Validity | C7: Values in a usable form: real email address, mobile in one pattern, real dates, numbers stored as numbers | D7: 0.3427 | E7: =(COUNTIF('Customer Master'!Q2:Q207,"Valid")+COUNTIF('Customer Master'!R2:R207,"Valid")+COUNT('Customer Master'!I2:L207))/(COUNTA('Customer Master'!D2:E207)+COUNTA('Customer Master'!A2:A207)*4) -> 1 | F7: =E7-D7 -> 0.6573
B8: Consistency | C8: One spelling per value: names in proper case, cities and provinces from the approved list, consent as Yes or No | D8: 0.4142 | E8: =(SUMPRODUCT(COUNTIF(CityList,'Customer Master'!F2:F207))+SUMPRODUCT(COUNTIF(ProvinceList,'Customer Master'!G2:G207))+COUNTIF('Customer Master'!N2:N207,"Yes")+COUNTIF('Customer Master'!N2:N207,"No"))/(COUNTA('Customer Master'!F2:G207)+COUNTA('Customer Master'!N2:N207)) -> 1 | F8: =E8-D8 -> 0.5858
B9: Uniqueness | C9: Each customer appears once (no repeated email or mobile number) | D9: 0.7687 | E9: =1-(COUNTIF('Customer Master'!Q2:Q207,"Duplicate")+COUNTIF('Customer Master'!R2:R207,"Duplicate"))/COUNTA('Customer Master'!A2:A207) -> 1 | F9: =E9-D9 -> 0.2313
